Workbook

Sheet Assumptions
A1: Revenue Architecture Model — MidMarket Scenario
A2: Blue = input (edit these). Black = formula. Green = link to another sheet.
A4: Horizon (months) | B4: 24
A5: Contract term (months) | B5: 12
A6: Implementation lag (months) | B6: 2
A8: AE — annual base ($) | B8: 95000
A9: AE — annual variable @ 100% ($) | B9: 95000
A10: AE — annual quota ($) | B10: 1100000
A11: BDR — annual base ($) | B11: 55000
A12: BDR — annual variable @ 100% ($) | B12: 30000
A13: BDR — monthly SQL quota | B13: 6
A15: Marketing leads/month | B15: 500
A16: Lead → MQL rate | B16: 0.3
A17: MQL → SQL rate | B17: 0.25
... A28: Renewal — annual contraction rate | B28: 0.03

Sheet Capacity & Bookings
A1: Capacity & Bookings
D3: Month → | E3: 1 | F3: 2 | G3: 3 | H3: 4 | I3: 5 | J3: 6 | K3: 7 | L3: 8 | M3: 9 | N3: 10 | O3: 11 | P3: 12 | Q3: 13 | R3: 14 | S3: 15 | T3: 16 | U3: 17 | V3: 18 | W3: 19 | X3: 20 | Y3: 21 | Z3: 22 | AA3: 23 | AB3: 24
A5: AE Roster
A6: AE-1 (existing) | B6: 1 | C6: Instant | D6: Ramp %: | E6: =IF(E$3<$B6,0,IF($C6="Instant",1,IF(E$3-$B6>=2,1,IF(E$3-$B6=1,0.66,0.33)))) -> 1 | F6: =IF(F$3<$B6,0,IF($C6="Instant",1,IF(F$3-$B6>=2,1,IF(F$3-$B6=1,0.66,0.33)))) -> 1 | G6: =IF(G$3<$B6,0,IF($C6="Instant",1,IF(G$3-$B6>=2,1,IF(G$3-$B6=1,0.66,0.33)))) -> 1 | H6: =IF(H$3<$B6,0,IF($C6="Instant",1,IF(H$3-$B6>=2,1,IF(H$3-$B6=1,0.66,0.33)))) -> 1 | I6: =IF(I$3<$B6,0,IF($C6="Instant",1,IF(I$3-$B6>=2,1,IF(I$3-$B6=1,0.66,0.33)))) -> 1 | J6: =IF(J$3<$B6,0,IF($C6="Instant",1,IF(J$3-$B6>=2,1,IF(J$3-$B6=1,0.66,0.33)))) -> 1 | K6: =IF(K$3<$B6,0,IF($C6="Instant",1,IF(K$3-$B6>=2,1,IF(K$3-$B6=1,0.66,0.33)))) -> 1 | L6: =IF(L$3<$B6,0,IF($C6="Instant",1,IF(L$3-$B6>=2,1,IF(L$3-$B6=1,0.66,0.33)))) -> 1 | ... AB6: =IF(AB$3<$B6,0,IF($C6="Instant",1,IF(AB$3-$B6>=2,1,IF(AB$3-$B6=1,0.66,0.33)))) -> 1
A7: AE-2 (existing) | B7: 1 | C7: Instant | D7: Ramp %: | E7: =IF(E$3<$B7,0,IF($C7="Instant",1,IF(E$3-$B7>=2,1,IF(E$3-$B7=1,0.66,0.33)))) -> 1 | F7: =IF(F$3<$B7,0,IF($C7="Instant",1,IF(F$3-$B7>=2,1,IF(F$3-$B7=1,0.66,0.33)))) -> 1 | G7: =IF(G$3<$B7,0,IF($C7="Instant",1,IF(G$3-$B7>=2,1,IF(G$3-$B7=1,0.66,0.33)))) -> 1 | H7: =IF(H$3<$B7,0,IF($C7="Instant",1,IF(H$3-$B7>=2,1,IF(H$3-$B7=1,0.66,0.33)))) -> 1 | I7: =IF(I$3<$B7,0,IF($C7="Instant",1,IF(I$3-$B7>=2,1,IF(I$3-$B7=1,0.66,0.33)))) -> 1 | J7: =IF(J$3<$B7,0,IF($C7="Instant",1,IF(J$3-$B7>=2,1,IF(J$3-$B7=1,0.66,0.33)))) -> 1 | K7: =IF(K$3<$B7,0,IF($C7="Instant",1,IF(K$3-$B7>=2,1,IF(K$3-$B7=1,0.66,0.33)))) -> 1 | L7: =IF(L$3<$B7,0,IF($C7="Instant",1,IF(L$3-$B7>=2,1,IF(L$3-$B7=1,0.66,0.33)))) -> 1 | ... AB7: =IF(AB$3<$B7,0,IF($C7="Instant",1,IF(AB$3-$B7>=2,1,IF(AB$3-$B7=1,0.66,0.33)))) -> 1
A8: AE-3 (new hire) | B8: 4 | C8: Standard | D8: Ramp %: | E8: =IF(E$3<$B8,0,IF($C8="Instant",1,IF(E$3-$B8>=2,1,IF(E$3-$B8=1,0.66,0.33)))) -> 0 | F8: =IF(F$3<$B8,0,IF($C8="Instant",1,IF(F$3-$B8>=2,1,IF(F$3-$B8=1,0.66,0.33)))) -> 0 | G8: =IF(G$3<$B8,0,IF($C8="Instant",1,IF(G$3-$B8>=2,1,IF(G$3-$B8=1,0.66,0.33)))) -> 0 | H8: =IF(H$3<$B8,0,IF($C8="Instant",1,IF(H$3-$B8>=2,1,IF(H$3-$B8=1,0.66,0.33)))) -> 0.33 | I8: =IF(I$3<$B8,0,IF($C8="Instant",1,IF(I$3-$B8>=2,1,IF(I$3-$B8=1,0.66,0.33)))) -> 0.66 | J8: =IF(J$3<$B8,0,IF($C8="Instant",1,IF(J$3-$B8>=2,1,IF(J$3-$B8=1,0.66,0.33)))) -> 1 | K8: =IF(K$3<$B8,0,IF($C8="Instant",1,IF(K$3-$B8>=2,1,IF(K$3-$B8=1,0.66,0.33)))) -> 1 | L8: =IF(L$3<$B8,0,IF($C8="Instant",1,IF(L$3-$B8>=2,1,IF(L$3-$B8=1,0.66,0.33)))) -> 1 | ... AB8: =IF(AB$3<$B8,0,IF($C8="Instant",1,IF(AB$3-$B8>=2,1,IF(AB$3-$B8=1,0.66,0.33)))) -> 1
A10: AE $ Capacity by Rep
A11: AE-1 (existing) | E11: =E6*(Assumptions!$B$10/12) -> 91666.667 | F11: =F6*(Assumptions!$B$10/12) -> 91666.667 | G11: =G6*(Assumptions!$B$10/12) -> 91666.667 | H11: =H6*(Assumptions!$B$10/12) -> 91666.667 | I11: =I6*(Assumptions!$B$10/12) -> 91666.667 | J11: =J6*(Assumptions!$B$10/12) -> 91666.667 | K11: =K6*(Assumptions!$B$10/12) -> 91666.667 | L11: =L6*(Assumptions!$B$10/12) -> 91666.667 | ... AB11: =AB6*(Assumptions!$B$10/12) -> 91666.667
A12: AE-2 (existing) | E12: =E7*(Assumptions!$B$10/12) -> 91666.667 | F12: =F7*(Assumptions!$B$10/12) -> 91666.667 | G12: =G7*(Assumptions!$B$10/12) -> 91666.667 | H12: =H7*(Assumptions!$B$10/12) -> 91666.667 | I12: =I7*(Assumptions!$B$10/12) -> 91666.667 | J12: =J7*(Assumptions!$B$10/12) -> 91666.667 | K12: =K7*(Assumptions!$B$10/12) -> 91666.667 | L12: =L7*(Assumptions!$B$10/12) -> 91666.667 | ... AB12: =AB7*(Assumptions!$B$10/12) -> 91666.667
A13: AE-3 (new hire) | E13: =E8*(Assumptions!$B$10/12) -> 0 | F13: =F8*(Assumptions!$B$10/12) -> 0 | G13: =G8*(Assumptions!$B$10/12) -> 0 | H13: =H8*(Assumptions!$B$10/12) -> 30250 | I13: =I8*(Assumptions!$B$10/12) -> 60500 | J13: =J8*(Assumptions!$B$10/12) -> 91666.667 | K13: =K8*(Assumptions!$B$10/12) -> 91666.667 | L13: =L8*(Assumptions!$B$10/12) -> 91666.667 | ... AB13: =AB8*(Assumptions!$B$10/12) -> 91666.667
A14: Total AE $ Capacity | E14: =E11+E12+E13 -> 183333.33 | F14: =F11+F12+F13 -> 183333.33 | G14: =G11+G12+G13 -> 183333.33 | H14: =H11+H12+H13 -> 213583.33 | I14: =I11+I12+I13 -> 243833.33 | J14: =J11+J12+J13 -> 275000 | K14: =K11+K12+K13 -> 275000 | L14: =L11+L12+L13 -> 275000 | ... AB14: =AB11+AB12+AB13 -> 275000
A16: AE Self-Sourced SQLs by Rep
A17: AE-1 (existing) | E17: =E6*Assumptions!$B$18 -> 2 | F17: =F6*Assumptions!$B$18 -> 2 | G17: =G6*Assumptions!$B$18 -> 2 | H17: =H6*Assumptions!$B$18 -> 2 | I17: =I6*Assumptions!$B$18 -> 2 | J17: =J6*Assumptions!$B$18 -> 2 | K17: =K6*Assumptions!$B$18 -> 2 | L17: =L6*Assumptions!$B$18 -> 2 | ... AB17: =AB6*Assumptions!$B$18 -> 2
A18: AE-2 (existing) | E18: =E7*Assumptions!$B$18 -> 2 | F18: =F7*Assumptions!$B$18 -> 2 | G18: =G7*Assumptions!$B$18 -> 2 | H18: =H7*Assumptions!$B$18 -> 2 | I18: =I7*Assumptions!$B$18 -> 2 | J18: =J7*Assumptions!$B$18 -> 2 | K18: =K7*Assumptions!$B$18 -> 2 | L18: =L7*Assumptions!$B$18 -> 2 | ... AB18: =AB7*Assumptions!$B$18 -> 2
A19: AE-3 (new hire) | E19: =E8*Assumptions!$B$18 -> 0 | F19: =F8*Assumptions!$B$18 -> 0 | G19: =G8*Assumptions!$B$18 -> 0 | H19: =H8*Assumptions!$B$18 -> 0.66 | I19: =I8*Assumptions!$B$18 -> 1.32 | J19: =J8*Assumptions!$B$18 -> 2 | K19: =K8*Assumptions!$B$18 -> 2 | L19: =L8*Assumptions!$B$18 -> 2 | ... AB19: =AB8*Assumptions!$B$18 -> 2
A20: Total AE Self-Sourced SQLs | E20: =E17+E18+E19 -> 4 | F20: =F17+F18+F19 -> 4 | G20: =G17+G18+G19 -> 4 | H20: =H17+H18+H19 -> 4.66 | I20: =I17+I18+I19 -> 5.32 | J20: =J17+J18+J19 -> 6 | K20: =K17+K18+K19 -> 6 | L20: =L17+L18+L19 -> 6 | ... AB20: =AB17+AB18+AB19 -> 6
A22: BDR Roster
A23: BDR-1 (existing) | B23: 1 | C23: Instant | E23: =IF(E$3<$B23,0,IF($C23="Instant",1,IF(E$3-$B23>=2,1,IF(E$3-$B23=1,0.66,0.33)))) -> 1 | F23: =IF(F$3<$B23,0,IF($C23="Instant",1,IF(F$3-$B23>=2,1,IF(F$3-$B23=1,0.66,0.33)))) -> 1 | G23: =IF(G$3<$B23,0,IF($C23="Instant",1,IF(G$3-$B23>=2,1,IF(G$3-$B23=1,0.66,0.33)))) -> 1 | H23: =IF(H$3<$B23,0,IF($C23="Instant",1,IF(H$3-$B23>=2,1,IF(H$3-$B23=1,0.66,0.33)))) -> 1 | I23: =IF(I$3<$B23,0,IF($C23="Instant",1,IF(I$3-$B23>=2,1,IF(I$3-$B23=1,0.66,0.33)))) -> 1 | J23: =IF(J$3<$B23,0,IF($C23="Instant",1,IF(J$3-$B23>=2,1,IF(J$3-$B23=1,0.66,0.33)))) -> 1 | K23: =IF(K$3<$B23,0,IF($C23="Instant",1,IF(K$3-$B23>=2,1,IF(K$3-$B23=1,0.66,0.33)))) -> 1 | L23: =IF(L$3<$B23,0,IF($C23="Instant",1,IF(L$3-$B23>=2,1,IF(L$3-$B23=1,0.66,0.33)))) -> 1 | ... AB23: =IF(AB$3<$B23,0,IF($C23="Instant",1,IF(AB$3-$B23>=2,1,IF(AB$3-$B23=1,0.66,0.33)))) -> 1
A24: BDR-2 (existing) | B24: 1 | C24: Instant | E24: =IF(E$3<$B24,0,IF($C24="Instant",1,IF(E$3-$B24>=2,1,IF(E$3-$B24=1,0.66,0.33)))) -> 1 | F24: =IF(F$3<$B24,0,IF($C24="Instant",1,IF(F$3-$B24>=2,1,IF(F$3-$B24=1,0.66,0.33)))) -> 1 | G24: =IF(G$3<$B24,0,IF($C24="Instant",1,IF(G$3-$B24>=2,1,IF(G$3-$B24=1,0.66,0.33)))) -> 1 | H24: =IF(H$3<$B24,0,IF($C24="Instant",1,IF(H$3-$B24>=2,1,IF(H$3-$B24=1,0.66,0.33)))) -> 1 | I24: =IF(I$3<$B24,0,IF($C24="Instant",1,IF(I$3-$B24>=2,1,IF(I$3-$B24=1,0.66,0.33)))) -> 1 | J24: =IF(J$3<$B24,0,IF($C24="Instant",1,IF(J$3-$B24>=2,1,IF(J$3-$B24=1,0.66,0.33)))) -> 1 | K24: =IF(K$3<$B24,0,IF($C24="Instant",1,IF(K$3-$B24>=2,1,IF(K$3-$B24=1,0.66,0.33)))) -> 1 | L24: =IF(L$3<$B24,0,IF($C24="Instant",1,IF(L$3-$B24>=2,1,IF(L$3-$B24=1,0.66,0.33)))) -> 1 | ... AB24: =IF(AB$3<$B24,0,IF($C24="Instant",1,IF(AB$3-$B24>=2,1,IF(AB$3-$B24=1,0.66,0.33)))) -> 1
A26: BDR SQLs by Rep
A27: BDR-1 (existing) | E27: =E23*Assumptions!$B$13 -> 6 | F27: =F23*Assumptions!$B$13 -> 6 | G27: =G23*Assumptions!$B$13 -> 6 | H27: =H23*Assumptions!$B$13 -> 6 | I27: =I23*Assumptions!$B$13 -> 6 | J27: =J23*Assumptions!$B$13 -> 6 | K27: =K23*Assumptions!$B$13 -> 6 | L27: =L23*Assumptions!$B$13 -> 6 | ... AB27: =AB23*Assumptions!$B$13 -> 6
A28: BDR-2 (existing) | E28: =E24*Assumptions!$B$13 -> 6 | F28: =F24*Assumptions!$B$13 -> 6 | G28: =G24*Assumptions!$B$13 -> 6 | H28: =H24*Assumptions!$B$13 -> 6 | I28: =I24*Assumptions!$B$13 -> 6 | J28: =J24*Assumptions!$B$13 -> 6 | K28: =K24*Assumptions!$B$13 -> 6 | L28: =L24*Assumptions!$B$13 -> 6 | ... AB28: =AB24*Assumptions!$B$13 -> 6
A29: Total BDR SQLs | E29: =E27+E28 -> 12 | F29: =F27+F28 -> 12 | G29: =G27+G28 -> 12 | H29: =H27+H28 -> 12 | I29: =I27+I28 -> 12 | J29: =J27+J28 -> 12 | K29: =K27+K28 -> 12 | L29: =L27+L28 -> 12 | ... AB29: =AB27+AB28 -> 12
A31: Marketing SQLs | E31: =Assumptions!$B$15*Assumptions!$B$16*Assumptions!$B$17 -> 37.5 | F31: =Assumptions!$B$15*Assumptions!$B$16*Assumptions!$B$17 -> 37.5 | G31: =Assumptions!$B$15*Assumptions!$B$16*Assumptions!$B$17 -> 37.5 | H31: =Assumptions!$B$15*Assumptions!$B$16*Assumptions!$B$17 -> 37.5 | I31: =Assumptions!$B$15*Assumptions!$B$16*Assumptions!$B$17 -> 37.5 | J31: =Assumptions!$B$15*Assumptions!$B$16*Assumptions!$B$17 -> 37.5 | K31: =Assumptions!$B$15*Assumptions!$B$16*Assumptions!$B$17 -> 37.5 | L31: =Assumptions!$B$15*Assumptions!$B$16*Assumptions!$B$17 -> 37.5 | ... AB31: =Assumptions!$B$15*Assumptions!$B$16*Assumptions!$B$17 -> 37.5
A33: Demand-Constrained Bookings ($) | E33: =E31*Assumptions!$B$21*Assumptions!$B$20+E29*Assumptions!$B$22*Assumptions!$B$20+E20*Assumptions!$B$23*Assumptions!$B$20 -> 237150 | F33: =F31*Assumptions!$B$21*Assumptions!$B$20+F29*Assumptions!$B$22*Assumptions!$B$20+F20*Assumptions!$B$23*Assumptions!$B$20 -> 237150 | G33: =G31*Assumptions!$B$21*Assumptions!$B$20+G29*Assumptions!$B$22*Assumptions!$B$20+G20*Assumptions!$B$23*Assumptions!$B$20 -> 237150 | H33: =H31*Assumptions!$B$21*Assumptions!$B$20+H29*Assumptions!$B$22*Assumptions!$B$20+H20*Assumptions!$B$23*Assumptions!$B$20 -> 241308 | I33: =I31*Assumptions!$B$21*Assumptions!$B$20+I29*Assumptions!$B$22*Assumptions!$B$20+I20*Assumptions!$B$23*Assumptions!$B$20 -> 245466 | J33: =J31*Assumptions!$B$21*Assumptions!$B$20+J29*Assumptions!$B$22*Assumptions!$B$20+J20*Assumptions!$B$23*Assumptions!$B$20 -> 249750 | K33: =K31*Assumptions!$B$21*Assumptions!$B$20+K29*Assumptions!$B$22*Assumptions!$B$20+K20*Assumptions!$B$23*Assumptions!$B$20 -> 249750 | L33: =L31*Assumptions!$B$21*Assumptions!$B$20+L29*Assumptions!$B$22*Assumptions!$B$20+L20*Assumptions!$B$23*Assumptions!$B$20 -> 249750 | ... AB33: =AB31*Assumptions!$B$21*Assumptions!$B$20+AB29*Assumptions!$B$22*Assumptions!$B$20+AB20*Assumptions!$B$23*Assumptions!$B$20 -> 249750
A34: Actual Bookings ($) | E34: =MIN(E14,E33)*Assumptions!$B$24 -> 183333.33 | F34: =MIN(F14,F33)*Assumptions!$B$24 -> 183333.33 | G34: =MIN(G14,G33)*Assumptions!$B$24 -> 183333.33 | H34: =MIN(H14,H33)*Assumptions!$B$24 -> 213583.33 | I34: =MIN(I14,I33)*Assumptions!$B$24 -> 243833.33 | J34: =MIN(J14,J33)*Assumptions!$B$24 -> 249750 | K34: =MIN(K14,K33)*Assumptions!$B$24 -> 249750 | L34: =MIN(L14,L33)*Assumptions!$B$24 -> 249750 | ... AB34: =MIN(AB14,AB33)*Assumptions!$B$24 -> 249750

Sheet Revenue Recognition
A1: Revenue Recognition — Cohort Waterfall
A2: Each row is one booking-month cohort. Gen 1 rows are the renewal of the Gen 0 cohort signed in the same original month, if it renews within the 24-month horizon. ARR = TCV since contract term = 12 months in this scenario.
D4: Month → | J4: 1 | K4: 2 | L4: 3 | M4: 4 | N4: 5 | O4: 6 | P4: 7 | Q4: 8 | R4: 9 | S4: 10 | T4: 11 | U4: 12 | V4: 13 | W4: 14 | X4: 15 | Y4: 16 | Z4: 17 | AA4: 18 | AB4: 19 | AC4: 20 | AD4: 21 | AE4: 22 | AF4: 23 | AG4: 24
A5: Cohort | B5: Signed Mo. | C5: Go-Live Mo. | D5: Rec. End Mo. | E5: Cohort ARR | F5: Churned $ | G5: Retained $ | H5: Expansion $ | I5: Contraction $
A6: Gen 0 — Month 1 | B6: 1 | C6: =B6+Assumptions!$B$6 -> 3 | D6: =C6+Assumptions!$B$5-1 -> 14 | E6: ='Capacity & Bookings'!E34 -> 183333.33 | J6: =IF(AND(J$4>=$C6,J$4<=$D6),$E6/Assumptions!$B$5,0) -> 0 | K6: =IF(AND(K$4>=$C6,K$4<=$D6),$E6/Assumptions!$B$5,0) -> 0 | L6: =IF(AND(L$4>=$C6,L$4<=$D6),$E6/Assumptions!$B$5,0) -> 15277.778 | M6: =IF(AND(M$4>=$C6,M$4<=$D6),$E6/Assumptions!$B$5,0) -> 15277.778 | N6: =IF(AND(N$4>=$C6,N$4<=$D6),$E6/Assumptions!$B$5,0) -> 15277.778 | O6: =IF(AND(O$4>=$C6,O$4<=$D6),$E6/Assumptions!$B$5,0) -> 15277.778 | P6: =IF(AND(P$4>=$C6,P$4<=$D6),$E6/Assumptions!$B$5,0) -> 15277.778 | Q6: =IF(AND(Q$4>=$C6,Q$4<=$D6),$E6/Assumptions!$B$5,0) -> 15277.778 | ... AG6: =IF(AND(AG$4>=$C6,AG$4<=$D6),$E6/Assumptions!$B$5,0) -> 0
A7: Gen 0 — Month 2 | B7: 2 | C7: =B7+Assumptions!$B$6 -> 4 | D7: =C7+Assumptions!$B$5-1 -> 15 | E7: ='Capacity & Bookings'!F34 -> 183333.33 | J7: =IF(AND(J$4>=$C7,J$4<=$D7),$E7/Assumptions!$B$5,0) -> 0 | K7: =IF(AND(K$4>=$C7,K$4<=$D7),$E7/Assumptions!$B$5,0) -> 0 | L7: =IF(AND(L$4>=$C7,L$4<=$D7),$E7/Assumptions!$B$5,0) -> 0 | M7: =IF(AND(M$4>=$C7,M$4<=$D7),$E7/Assumptions!$B$5,0) -> 15277.778 | N7: =IF(AND(N$4>=$C7,N$4<=$D7),$E7/Assumptions!$B$5,0) -> 15277.778 | O7: =IF(AND(O$4>=$C7,O$4<=$D7),$E7/Assumptions!$B$5,0) -> 15277.778 | P7: =IF(AND(P$4>=$C7,P$4<=$D7),$E7/Assumptions!$B$5,0) -> 15277.778 | Q7: =IF(AND(Q$4>=$C7,Q$4<=$D7),$E7/Assumptions!$B$5,0) -> 15277.778 | ... AG7: =IF(AND(AG$4>=$C7,AG$4<=$D7),$E7/Assumptions!$B$5,0) -> 0
A8: Gen 0 — Month 3 | B8: 3 | C8: =B8+Assumptions!$B$6 -> 5 | D8: =C8+Assumptions!$B$5-1 -> 16 | E8: ='Capacity & Bookings'!G34 -> 183333.33 | J8: =IF(AND(J$4>=$C8,J$4<=$D8),$E8/Assumptions!$B$5,0) -> 0 | K8: =IF(AND(K$4>=$C8,K$4<=$D8),$E8/Assumptions!$B$5,0) -> 0 | L8: =IF(AND(L$4>=$C8,L$4<=$D8),$E8/Assumptions!$B$5,0) -> 0 | M8: =IF(AND(M$4>=$C8,M$4<=$D8),$E8/Assumptions!$B$5,0) -> 0 | N8: =IF(AND(N$4>=$C8,N$4<=$D8),$E8/Assumptions!$B$5,0) -> 15277.778 | O8: =IF(AND(O$4>=$C8,O$4<=$D8),$E8/Assumptions!$B$5,0) -> 15277.778 | P8: =IF(AND(P$4>=$C8,P$4<=$D8),$E8/Assumptions!$B$5,0) -> 15277.778 | Q8: =IF(AND(Q$4>=$C8,Q$4<=$D8),$E8/Assumptions!$B$5,0) -> 15277.778 | ... AG8: =IF(AND(AG$4>=$C8,AG$4<=$D8),$E8/Assumptions!$B$5,0) -> 0
A9: Gen 0 — Month 4 | B9: 4 | C9: =B9+Assumptions!$B$6 -> 6 | D9: =C9+Assumptions!$B$5-1 -> 17 | E9: ='Capacity & Bookings'!H34 -> 213583.33 | J9: =IF(AND(J$4>=$C9,J$4<=$D9),$E9/Assumptions!$B$5,0) -> 0 | K9: =IF(AND(K$4>=$C9,K$4<=$D9),$E9/Assumptions!$B$5,0) -> 0 | L9: =IF(AND(L$4>=$C9,L$4<=$D9),$E9/Assumptions!$B$5,0) -> 0 | M9: =IF(AND(M$4>=$C9,M$4<=$D9),$E9/Assumptions!$B$5,0) -> 0 | N9: =IF(AND(N$4>=$C9,N$4<=$D9),$E9/Assumptions!$B$5,0) -> 0 | O9: =IF(AND(O$4>=$C9,O$4<=$D9),$E9/Assumptions!$B$5,0) -> 17798.611 | P9: =IF(AND(P$4>=$C9,P$4<=$D9),$E9/Assumptions!$B$5,0) -> 17798.611 | Q9: =IF(AND(Q$4>=$C9,Q$4<=$D9),$E9/Assumptions!$B$5,0) -> 17798.611 | ... AG9: =IF(AND(AG$4>=$C9,AG$4<=$D9),$E9/Assumptions!$B$5,0) -> 0
A10: Gen 0 — Month 5 | B10: 5 | C10: =B10+Assumptions!$B$6 -> 7 | D10: =C10+Assumptions!$B$5-1 -> 18 | E10: ='Capacity & Bookings'!I34 -> 243833.33 | J10: =IF(AND(J$4>=$C10,J$4<=$D10),$E10/Assumptions!$B$5,0) -> 0 | K10: =IF(AND(K$4>=$C10,K$4<=$D10),$E10/Assumptions!$B$5,0) -> 0 | L10: =IF(AND(L$4>=$C10,L$4<=$D10),$E10/Assumptions!$B$5,0) -> 0 | M10: =IF(AND(M$4>=$C10,M$4<=$D10),$E10/Assumptions!$B$5,0) -> 0 | N10: =IF(AND(N$4>=$C10,N$4<=$D10),$E10/Assumptions!$B$5,0) -> 0 | O10: =IF(AND(O$4>=$C10,O$4<=$D10),$E10/Assumptions!$B$5,0) -> 0 | P10: =IF(AND(P$4>=$C10,P$4<=$D10),$E10/Assumptions!$B$5,0) -> 20319.444 | Q10: =IF(AND(Q$4>=$C10,Q$4<=$D10),$E10/Assumptions!$B$5,0) -> 20319.444 | ... AG10: =IF(AND(AG$4>=$C10,AG$4<=$D10),$E10/Assumptions!$B$5,0) -> 0
A11: Gen 0 — Month 6 | B11: 6 | C11: =B11+Assumptions!$B$6 -> 8 | D11: =C11+Assumptions!$B$5-1 -> 19 | E11: ='Capacity & Bookings'!J34 -> 249750 | J11: =IF(AND(J$4>=$C11,J$4<=$D11),$E11/Assumptions!$B$5,0) -> 0 | K11: =IF(AND(K$4>=$C11,K$4<=$D11),$E11/Assumptions!$B$5,0) -> 0 | L11: =IF(AND(L$4>=$C11,L$4<=$D11),$E11/Assumptions!$B$5,0) -> 0 | M11: =IF(AND(M$4>=$C11,M$4<=$D11),$E11/Assumptions!$B$5,0) -> 0 | N11: =IF(AND(N$4>=$C11,N$4<=$D11),$E11/Assumptions!$B$5,0) -> 0 | O11: =IF(AND(O$4>=$C11,O$4<=$D11),$E11/Assumptions!$B$5,0) -> 0 | P11: =IF(AND(P$4>=$C11,P$4<=$D11),$E11/Assumptions!$B$5,0) -> 0 | Q11: =IF(AND(Q$4>=$C11,Q$4<=$D11),$E11/Assumptions!$B$5,0) -> 20812.5 | ... AG11: =IF(AND(AG$4>=$C11,AG$4<=$D11),$E11/Assumptions!$B$5,0) -> 0
A12: Gen 0 — Month 7 | B12: 7 | C12: =B12+Assumptions!$B$6 -> 9 | D12: =C12+Assumptions!$B$5-1 -> 20 | E12: ='Capacity & Bookings'!K34 -> 249750 | J12: =IF(AND(J$4>=$C12,J$4<=$D12),$E12/Assumptions!$B$5,0) -> 0 | K12: =IF(AND(K$4>=$C12,K$4<=$D12),$E12/Assumptions!$B$5,0) -> 0 | L12: =IF(AND(L$4>=$C12,L$4<=$D12),$E12/Assumptions!$B$5,0) -> 0 | M12: =IF(AND(M$4>=$C12,M$4<=$D12),$E12/Assumptions!$B$5,0) -> 0 | N12: =IF(AND(N$4>=$C12,N$4<=$D12),$E12/Assumptions!$B$5,0) -> 0 | O12: =IF(AND(O$4>=$C12,O$4<=$D12),$E12/Assumptions!$B$5,0) -> 0 | P12: =IF(AND(P$4>=$C12,P$4<=$D12),$E12/Assumptions!$B$5,0) -> 0 | Q12: =IF(AND(Q$4>=$C12,Q$4<=$D12),$E12/Assumptions!$B$5,0) -> 0 | ... AG12: =IF(AND(AG$4>=$C12,AG$4<=$D12),$E12/Assumptions!$B$5,0) -> 0
A13: Gen 0 — Month 8 | B13: 8 | C13: =B13+Assumptions!$B$6 -> 10 | D13: =C13+Assumptions!$B$5-1 -> 21 | E13: ='Capacity & Bookings'!L34 -> 249750 | J13: =IF(AND(J$4>=$C13,J$4<=$D13),$E13/Assumptions!$B$5,0) -> 0 | K13: =IF(AND(K$4>=$C13,K$4<=$D13),$E13/Assumptions!$B$5,0) -> 0 | L13: =IF(AND(L$4>=$C13,L$4<=$D13),$E13/Assumptions!$B$5,0) -> 0 | M13: =IF(AND(M$4>=$C13,M$4<=$D13),$E13/Assumptions!$B$5,0) -> 0 | N13: =IF(AND(N$4>=$C13,N$4<=$D13),$E13/Assumptions!$B$5,0) -> 0 | O13: =IF(AND(O$4>=$C13,O$4<=$D13),$E13/Assumptions!$B$5,0) -> 0 | P13: =IF(AND(P$4>=$C13,P$4<=$D13),$E13/Assumptions!$B$5,0) -> 0 | Q13: =IF(AND(Q$4>=$C13,Q$4<=$D13),$E13/Assumptions!$B$5,0) -> 0 | ... AG13: =IF(AND(AG$4>=$C13,AG$4<=$D13),$E13/Assumptions!$B$5,0) -> 0
A14: Gen 0 — Month 9 | B14: 9 | C14: =B14+Assumptions!$B$6 -> 11 | D14: =C14+Assumptions!$B$5-1 -> 22 | E14: ='Capacity & Bookings'!M34 -> 249750 | J14: =IF(AND(J$4>=$C14,J$4<=$D14),$E14/Assumptions!$B$5,0) -> 0 | K14: =IF(AND(K$4>=$C14,K$4<=$D14),$E14/Assumptions!$B$5,0) -> 0 | L14: =IF(AND(L$4>=$C14,L$4<=$D14),$E14/Assumptions!$B$5,0) -> 0 | M14: =IF(AND(M$4>=$C14,M$4<=$D14),$E14/Assumptions!$B$5,0) -> 0 | N14: =IF(AND(N$4>=$C14,N$4<=$D14),$E14/Assumptions!$B$5,0) -> 0 | O14: =IF(AND(O$4>=$C14,O$4<=$D14),$E14/Assumptions!$B$5,0) -> 0 | P14: =IF(AND(P$4>=$C14,P$4<=$D14),$E14/Assumptions!$B$5,0) -> 0 | Q14: =IF(AND(Q$4>=$C14,Q$4<=$D14),$E14/Assumptions!$B$5,0) -> 0 | ... AG14: =IF(AND(AG$4>=$C14,AG$4<=$D14),$E14/Assumptions!$B$5,0) -> 0
A15: Gen 0 — Month 10 | B15: 10 | C15: =B15+Assumptions!$B$6 -> 12 | D15: =C15+Assumptions!$B$5-1 -> 23 | E15: ='Capacity & Bookings'!N34 -> 249750 | J15: =IF(AND(J$4>=$C15,J$4<=$D15),$E15/Assumptions!$B$5,0) -> 0 | K15: =IF(AND(K$4>=$C15,K$4<=$D15),$E15/Assumptions!$B$5,0) -> 0 | L15: =IF(AND(L$4>=$C15,L$4<=$D15),$E15/Assumptions!$B$5,0) -> 0 | M15: =IF(AND(M$4>=$C15,M$4<=$D15),$E15/Assumptions!$B$5,0) -> 0 | N15: =IF(AND(N$4>=$C15,N$4<=$D15),$E15/Assumptions!$B$5,0) -> 0 | O15: =IF(AND(O$4>=$C15,O$4<=$D15),$E15/Assumptions!$B$5,0) -> 0 | P15: =IF(AND(P$4>=$C15,P$4<=$D15),$E15/Assumptions!$B$5,0) -> 0 | Q15: =IF(AND(Q$4>=$C15,Q$4<=$D15),$E15/Assumptions!$B$5,0) -> 0 | ... AG15: =IF(AND(AG$4>=$C15,AG$4<=$D15),$E15/Assumptions!$B$5,0) -> 0
A16: Gen 0 — Month 11 | B16: 11 | C16: =B16+Assumptions!$B$6 -> 13 | D16: =C16+Assumptions!$B$5-1 -> 24 | E16: ='Capacity & Bookings'!O34 -> 249750 | J16: =IF(AND(J$4>=$C16,J$4<=$D16),$E16/Assumptions!$B$5,0) -> 0 | K16: =IF(AND(K$4>=$C16,K$4<=$D16),$E16/Assumptions!$B$5,0) -> 0 | L16: =IF(AND(L$4>=$C16,L$4<=$D16),$E16/Assumptions!$B$5,0) -> 0 | M16: =IF(AND(M$4>=$C16,M$4<=$D16),$E16/Assumptions!$B$5,0) -> 0 | N16: =IF(AND(N$4>=$C16,N$4<=$D16),$E16/Assumptions!$B$5,0) -> 0 | O16: =IF(AND(O$4>=$C16,O$4<=$D16),$E16/Assumptions!$B$5,0) -> 0 | P16: =IF(AND(P$4>=$C16,P$4<=$D16),$E16/Assumptions!$B$5,0) -> 0 | Q16: =IF(AND(Q$4>=$C16,Q$4<=$D16),$E16/Assumptions!$B$5,0) -> 0 | ... AG16: =IF(AND(AG$4>=$C16,AG$4<=$D16),$E16/Assumptions!$B$5,0) -> 20812.5
A17: Gen 0 — Month 12 | B17: 12 | C17: =B17+Assumptions!$B$6 -> 14 | D17: =C17+Assumptions!$B$5-1 -> 25 | E17: ='Capacity & Bookings'!P34 -> 249750 | J17: =IF(AND(J$4>=$C17,J$4<=$D17),$E17/Assumptions!$B$5,0) -> 0 | K17: =IF(AND(K$4>=$C17,K$4<=$D17),$E17/Assumptions!$B$5,0) -> 0 | L17: =IF(AND(L$4>=$C17,L$4<=$D17),$E17/Assumptions!$B$5,0) -> 0 | M17: =IF(AND(M$4>=$C17,M$4<=$D17),$E17/Assumptions!$B$5,0) -> 0 | N17: =IF(AND(N$4>=$C17,N$4<=$D17),$E17/Assumptions!$B$5,0) -> 0 | O17: =IF(AND(O$4>=$C17,O$4<=$D17),$E17/Assumptions!$B$5,0) -> 0 | P17: =IF(AND(P$4>=$C17,P$4<=$D17),$E17/Assumptions!$B$5,0) -> 0 | Q17: =IF(AND(Q$4>=$C17,Q$4<=$D17),$E17/Assumptions!$B$5,0) -> 0 | ... AG17: =IF(AND(AG$4>=$C17,AG$4<=$D17),$E17/Assumptions!$B$5,0) -> 20812.5
A18: Gen 0 — Month 13 | B18: 13 | C18: =B18+Assumptions!$B$6 -> 15 | D18: =C18+Assumptions!$B$5-1 -> 26 | E18: ='Capacity & Bookings'!Q34 -> 249750 | J18: =IF(AND(J$4>=$C18,J$4<=$D18),$E18/Assumptions!$B$5,0) -> 0 | K18: =IF(AND(K$4>=$C18,K$4<=$D18),$E18/Assumptions!$B$5,0) -> 0 | L18: =IF(AND(L$4>=$C18,L$4<=$D18),$E18/Assumptions!$B$5,0) -> 0 | M18: =IF(AND(M$4>=$C18,M$4<=$D18),$E18/Assumptions!$B$5,0) -> 0 | N18: =IF(AND(N$4>=$C18,N$4<=$D18),$E18/Assumptions!$B$5,0) -> 0 | O18: =IF(AND(O$4>=$C18,O$4<=$D18),$E18/Assumptions!$B$5,0) -> 0 | P18: =IF(AND(P$4>=$C18,P$4<=$D18),$E18/Assumptions!$B$5,0) -> 0 | Q18: =IF(AND(Q$4>=$C18,Q$4<=$D18),$E18/Assumptions!$B$5,0) -> 0 | ... AG18: =IF(AND(AG$4>=$C18,AG$4<=$D18),$E18/Assumptions!$B$5,0) -> 20812.5
A19: Gen 0 — Month 14 | B19: 14 | C19: =B19+Assumptions!$B$6 -> 16 | D19: =C19+Assumptions!$B$5-1 -> 27 | E19: ='Capacity & Bookings'!R34 -> 249750 | J19: =IF(AND(J$4>=$C19,J$4<=$D19),$E19/Assumptions!$B$5,0) -> 0 | K19: =IF(AND(K$4>=$C19,K$4<=$D19),$E19/Assumptions!$B$5,0) -> 0 | L19: =IF(AND(L$4>=$C19,L$4<=$D19),$E19/Assumptions!$B$5,0) -> 0 | M19: =IF(AND(M$4>=$C19,M$4<=$D19),$E19/Assumptions!$B$5,0) -> 0 | N19: =IF(AND(N$4>=$C19,N$4<=$D19),$E19/Assumptions!$B$5,0) -> 0 | O19: =IF(AND(O$4>=$C19,O$4<=$D19),$E19/Assumptions!$B$5,0) -> 0 | P19: =IF(AND(P$4>=$C19,P$4<=$D19),$E19/Assumptions!$B$5,0) -> 0 | Q19: =IF(AND(Q$4>=$C19,Q$4<=$D19),$E19/Assumptions!$B$5,0) -> 0 | ... AG19: =IF(AND(AG$4>=$C19,AG$4<=$D19),$E19/Assumptions!$B$5,0) -> 20812.5
A20: Gen 0 — Month 15 | B20: 15 | C20: =B20+Assumptions!$B$6 -> 17 | D20: =C20+Assumptions!$B$5-1 -> 28 | E20: ='Capacity & Bookings'!S34 -> 249750 | J20: =IF(AND(J$4>=$C20,J$4<=$D20),$E20/Assumptions!$B$5,0) -> 0 | K20: =IF(AND(K$4>=$C20,K$4<=$D20),$E20/Assumptions!$B$5,0) -> 0 | L20: =IF(AND(L$4>=$C20,L$4<=$D20),$E20/Assumptions!$B$5,0) -> 0 | M20: =IF(AND(M$4>=$C20,M$4<=$D20),$E20/Assumptions!$B$5,0) -> 0 | N20: =IF(AND(N$4>=$C20,N$4<=$D20),$E20/Assumptions!$B$5,0) -> 0 | O20: =IF(AND(O$4>=$C20,O$4<=$D20),$E20/Assumptions!$B$5,0) -> 0 | P20: =IF(AND(P$4>=$C20,P$4<=$D20),$E20/Assumptions!$B$5,0) -> 0 | Q20: =IF(AND(Q$4>=$C20,Q$4<=$D20),$E20/Assumptions!$B$5,0) -> 0 | ... AG20: =IF(AND(AG$4>=$C20,AG$4<=$D20),$E20/Assumptions!$B$5,0) -> 20812.5
A21: Gen 0 — Month 16 | B21: 16 | C21: =B21+Assumptions!$B$6 -> 18 | D21: =C21+Assumptions!$B$5-1 -> 29 | E21: ='Capacity & Bookings'!T34 -> 249750 | J21: =IF(AND(J$4>=$C21,J$4<=$D21),$E21/Assumptions!$B$5,0) -> 0 | K21: =IF(AND(K$4>=$C21,K$4<=$D21),$E21/Assumptions!$B$5,0) -> 0 | L21: =IF(AND(L$4>=$C21,L$4<=$D21),$E21/Assumptions!$B$5,0) -> 0 | M21: =IF(AND(M$4>=$C21,M$4<=$D21),$E21/Assumptions!$B$5,0) -> 0 | N21: =IF(AND(N$4>=$C21,N$4<=$D21),$E21/Assumptions!$B$5,0) -> 0 | O21: =IF(AND(O$4>=$C21,O$4<=$D21),$E21/Assumptions!$B$5,0) -> 0 | P21: =IF(AND(P$4>=$C21,P$4<=$D21),$E21/Assumptions!$B$5,0) -> 0 | Q21: =IF(AND(Q$4>=$C21,Q$4<=$D21),$E21/Assumptions!$B$5,0) -> 0 | ... AG21: =IF(AND(AG$4>=$C21,AG$4<=$D21),$E21/Assumptions!$B$5,0) -> 20812.5
A22: Gen 0 — Month 17 | B22: 17 | C22: =B22+Assumptions!$B$6 -> 19 | D22: =C22+Assumptions!$B$5-1 -> 30 | E22: ='Capacity & Bookings'!U34 -> 249750 | J22: =IF(AND(J$4>=$C22,J$4<=$D22),$E22/Assumptions!$B$5,0) -> 0 | K22: =IF(AND(K$4>=$C22,K$4<=$D22),$E22/Assumptions!$B$5,0) -> 0 | L22: =IF(AND(L$4>=$C22,L$4<=$D22),$E22/Assumptions!$B$5,0) -> 0 | M22: =IF(AND(M$4>=$C22,M$4<=$D22),$E22/Assumptions!$B$5,0) -> 0 | N22: =IF(AND(N$4>=$C22,N$4<=$D22),$E22/Assumptions!$B$5,0) -> 0 | O22: =IF(AND(O$4>=$C22,O$4<=$D22),$E22/Assumptions!$B$5,0) -> 0 | P22: =IF(AND(P$4>=$C22,P$4<=$D22),$E22/Assumptions!$B$5,0) -> 0 | Q22: =IF(AND(Q$4>=$C22,Q$4<=$D22),$E22/Assumptions!$B$5,0) -> 0 | ... AG22: =IF(AND(AG$4>=$C22,AG$4<=$D22),$E22/Assumptions!$B$5,0) -> 20812.5
A23: Gen 0 — Month 18 | B23: 18 | C23: =B23+Assumptions!$B$6 -> 20 | D23: =C23+Assumptions!$B$5-1 -> 31 | E23: ='Capacity & Bookings'!V34 -> 249750 | J23: =IF(AND(J$4>=$C23,J$4<=$D23),$E23/Assumptions!$B$5,0) -> 0 | K23: =IF(AND(K$4>=$C23,K$4<=$D23),$E23/Assumptions!$B$5,0) -> 0 | L23: =IF(AND(L$4>=$C23,L$4<=$D23),$E23/Assumptions!$B$5,0) -> 0 | M23: =IF(AND(M$4>=$C23,M$4<=$D23),$E23/Assumptions!$B$5,0) -> 0 | N23: =IF(AND(N$4>=$C23,N$4<=$D23),$E23/Assumptions!$B$5,0) -> 0 | O23: =IF(AND(O$4>=$C23,O$4<=$D23),$E23/Assumptions!$B$5,0) -> 0 | P23: =IF(AND(P$4>=$C23,P$4<=$D23),$E23/Assumptions!$B$5,0) -> 0 | Q23: =IF(AND(Q$4>=$C23,Q$4<=$D23),$E23/Assumptions!$B$5,0) -> 0 | ... AG23: =IF(AND(AG$4>=$C23,AG$4<=$D23),$E23/Assumptions!$B$5,0) -> 20812.5
A24: Gen 0 — Month 19 | B24: 19 | C24: =B24+Assumptions!$B$6 -> 21 | D24: =C24+Assumptions!$B$5-1 -> 32 | E24: ='Capacity & Bookings'!W34 -> 249750 | J24: =IF(AND(J$4>=$C24,J$4<=$D24),$E24/Assumptions!$B$5,0) -> 0 | K24: =IF(AND(K$4>=$C24,K$4<=$D24),$E24/Assumptions!$B$5,0) -> 0 | L24: =IF(AND(L$4>=$C24,L$4<=$D24),$E24/Assumptions!$B$5,0) -> 0 | M24: =IF(AND(M$4>=$C24,M$4<=$D24),$E24/Assumptions!$B$5,0) -> 0 | N24: =IF(AND(N$4>=$C24,N$4<=$D24),$E24/Assumptions!$B$5,0) -> 0 | O24: =IF(AND(O$4>=$C24,O$4<=$D24),$E24/Assumptions!$B$5,0) -> 0 | P24: =IF(AND(P$4>=$C24,P$4<=$D24),$E24/Assumptions!$B$5,0) -> 0 | Q24: =IF(AND(Q$4>=$C24,Q$4<=$D24),$E24/Assumptions!$B$5,0) -> 0 | ... AG24: =IF(AND(AG$4>=$C24,AG$4<=$D24),$E24/Assumptions!$B$5,0) -> 20812.5
A25: Gen 0 — Month 20 | B25: 20 | C25: =B25+Assumptions!$B$6 -> 22 | D25: =C25+Assumptions!$B$5-1 -> 33 | E25: ='Capacity & Bookings'!X34 -> 249750 | J25: =IF(AND(J$4>=$C25,J$4<=$D25),$E25/Assumptions!$B$5,0) -> 0 | K25: =IF(AND(K$4>=$C25,K$4<=$D25),$E25/Assumptions!$B$5,0) -> 0 | L25: =IF(AND(L$4>=$C25,L$4<=$D25),$E25/Assumptions!$B$5,0) -> 0 | M25: =IF(AND(M$4>=$C25,M$4<=$D25),$E25/Assumptions!$B$5,0) -> 0 | N25: =IF(AND(N$4>=$C25,N$4<=$D25),$E25/Assumptions!$B$5,0) -> 0 | O25: =IF(AND(O$4>=$C25,O$4<=$D25),$E25/Assumptions!$B$5,0) -> 0 | P25: =IF(AND(P$4>=$C25,P$4<=$D25),$E25/Assumptions!$B$5,0) -> 0 | Q25: =IF(AND(Q$4>=$C25,Q$4<=$D25),$E25/Assumptions!$B$5,0) -> 0 | ... AG25: =IF(AND(AG$4>=$C25,AG$4<=$D25),$E25/Assumptions!$B$5,0) -> 20812.5
A26: Gen 0 — Month 21 | B26: 21 | C26: =B26+Assumptions!$B$6 -> 23 | D26: =C26+Assumptions!$B$5-1 -> 34 | E26: ='Capacity & Bookings'!Y34 -> 249750 | J26: =IF(AND(J$4>=$C26,J$4<=$D26),$E26/Assumptions!$B$5,0) -> 0 | K26: =IF(AND(K$4>=$C26,K$4<=$D26),$E26/Assumptions!$B$5,0) -> 0 | L26: =IF(AND(L$4>=$C26,L$4<=$D26),$E26/Assumptions!$B$5,0) -> 0 | M26: =IF(AND(M$4>=$C26,M$4<=$D26),$E26/Assumptions!$B$5,0) -> 0 | N26: =IF(AND(N$4>=$C26,N$4<=$D26),$E26/Assumptions!$B$5,0) -> 0 | O26: =IF(AND(O$4>=$C26,O$4<=$D26),$E26/Assumptions!$B$5,0) -> 0 | P26: =IF(AND(P$4>=$C26,P$4<=$D26),$E26/Assumptions!$B$5,0) -> 0 | Q26: =IF(AND(Q$4>=$C26,Q$4<=$D26),$E26/Assumptions!$B$5,0) -> 0 | ... AG26: =IF(AND(AG$4>=$C26,AG$4<=$D26),$E26/Assumptions!$B$5,0) -> 20812.5
A27: Gen 0 — Month 22 | B27: 22 | C27: =B27+Assumptions!$B$6 -> 24 | D27: =C27+Assumptions!$B$5-1 -> 35 | E27: ='Capacity & Bookings'!Z34 -> 249750 | J27: =IF(AND(J$4>=$C27,J$4<=$D27),$E27/Assumptions!$B$5,0) -> 0 | K27: =IF(AND(K$4>=$C27,K$4<=$D27),$E27/Assumptions!$B$5,0) -> 0 | L27: =IF(AND(L$4>=$C27,L$4<=$D27),$E27/Assumptions!$B$5,0) -> 0 | M27: =IF(AND(M$4>=$C27,M$4<=$D27),$E27/Assumptions!$B$5,0) -> 0 | N27: =IF(AND(N$4>=$C27,N$4<=$D27),$E27/Assumptions!$B$5,0) -> 0 | O27: =IF(AND(O$4>=$C27,O$4<=$D27),$E27/Assumptions!$B$5,0) -> 0 | P27: =IF(AND(P$4>=$C27,P$4<=$D27),$E27/Assumptions!$B$5,0) -> 0 | Q27: =IF(AND(Q$4>=$C27,Q$4<=$D27),$E27/Assumptions!$B$5,0) -> 0 | ... AG27: =IF(AND(AG$4>=$C27,AG$4<=$D27),$E27/Assumptions!$B$5,0) -> 20812.5
A28: Gen 0 — Month 23 | B28: 23 | C28: =B28+Assumptions!$B$6 -> 25 | D28: =C28+Assumptions!$B$5-1 -> 36 | E28: ='Capacity & Bookings'!AA34 -> 249750 | J28: =IF(AND(J$4>=$C28,J$4<=$D28),$E28/Assumptions!$B$5,0) -> 0 | K28: =IF(AND(K$4>=$C28,K$4<=$D28),$E28/Assumptions!$B$5,0) -> 0 | L28: =IF(AND(L$4>=$C28,L$4<=$D28),$E28/Assumptions!$B$5,0) -> 0 | M28: =IF(AND(M$4>=$C28,M$4<=$D28),$E28/Assumptions!$B$5,0) -> 0 | N28: =IF(AND(N$4>=$C28,N$4<=$D28),$E28/Assumptions!$B$5,0) -> 0 | O28: =IF(AND(O$4>=$C28,O$4<=$D28),$E28/Assumptions!$B$5,0) -> 0 | P28: =IF(AND(P$4>=$C28,P$4<=$D28),$E28/Assumptions!$B$5,0) -> 0 | Q28: =IF(AND(Q$4>=$C28,Q$4<=$D28),$E28/Assumptions!$B$5,0) -> 0 | ... AG28: =IF(AND(AG$4>=$C28,AG$4<=$D28),$E28/Assumptions!$B$5,0) -> 0
A29: Gen 0 — Month 24 | B29: 24 | C29: =B29+Assumptions!$B$6 -> 26 | D29: =C29+Assumptions!$B$5-1 -> 37 | E29: ='Capacity & Bookings'!AB34 -> 249750 | J29: =IF(AND(J$4>=$C29,J$4<=$D29),$E29/Assumptions!$B$5,0) -> 0 | K29: =IF(AND(K$4>=$C29,K$4<=$D29),$E29/Assumptions!$B$5,0) -> 0 | L29: =IF(AND(L$4>=$C29,L$4<=$D29),$E29/Assumptions!$B$5,0) -> 0 | M29: =IF(AND(M$4>=$C29,M$4<=$D29),$E29/Assumptions!$B$5,0) -> 0 | N29: =IF(AND(N$4>=$C29,N$4<=$D29),$E29/Assumptions!$B$5,0) -> 0 | O29: =IF(AND(O$4>=$C29,O$4<=$D29),$E29/Assumptions!$B$5,0) -> 0 | P29: =IF(AND(P$4>=$C29,P$4<=$D29),$E29/Assumptions!$B$5,0) -> 0 | Q29: =IF(AND(Q$4>=$C29,Q$4<=$D29),$E29/Assumptions!$B$5,0) -> 0 | ... AG29: =IF(AND(AG$4>=$C29,AG$4<=$D29),$E29/Assumptions!$B$5,0) -> 0
A31: Renewal Generation 1
A32: Gen 1 — renews Gen0 Mo.1 | B32: =D6+1 -> 15 | C32: =B32 -> 15 | D32: =C32+Assumptions!$B$5-1 -> 26 | E32: =G32+H32-I32 -> 185533.33 | F32: =E6*Assumptions!$B$26 -> 22000 | G32: =E6-F32 -> 161333.33 | H32: =G32*Assumptions!$B$27 -> 29040 | I32: =G32*Assumptions!$B$28 -> 4840 | J32: =IF(AND(J$4>=$C32,J$4<=$D32),$E32/Assumptions!$B$5,0) -> 0 | K32: =IF(AND(K$4>=$C32,K$4<=$D32),$E32/Assumptions!$B$5,0) -> 0 | L32: =IF(AND(L$4>=$C32,L$4<=$D32),$E32/Assumptions!$B$5,0) -> 0 | M32: =IF(AND(M$4>=$C32,M$4<=$D32),$E32/Assumptions!$B$5,0) -> 0 | N32: =IF(AND(N$4>=$C32,N$4<=$D32),$E32/Assumptions!$B$5,0) -> 0 | O32: =IF(AND(O$4>=$C32,O$4<=$D32),$E32/Assumptions!$B$5,0) -> 0 | P32: =IF(AND(P$4>=$C32,P$4<=$D32),$E32/Assumptions!$B$5,0) -> 0 | Q32: =IF(AND(Q$4>=$C32,Q$4<=$D32),$E32/Assumptions!$B$5,0) -> 0 | ... AG32: =IF(AND(AG$4>=$C32,AG$4<=$D32),$E32/Assumptions!$B$5,0) -> 15461.111
A33: Gen 1 — renews Gen0 Mo.2 | B33: =D7+1 -> 16 | C33: =B33 -> 16 | D33: =C33+Assumptions!$B$5-1 -> 27 | E33: =G33+H33-I33 -> 185533.33 | F33: =E7*Assumptions!$B$26 -> 22000 | G33: =E7-F33 -> 161333.33 | H33: =G33*Assumptions!$B$27 -> 29040 | I33: =G33*Assumptions!$B$28 -> 4840 | J33: =IF(AND(J$4>=$C33,J$4<=$D33),$E33/Assumptions!$B$5,0) -> 0 | K33: =IF(AND(K$4>=$C33,K$4<=$D33),$E33/Assumptions!$B$5,0) -> 0 | L33: =IF(AND(L$4>=$C33,L$4<=$D33),$E33/Assumptions!$B$5,0) -> 0 | M33: =IF(AND(M$4>=$C33,M$4<=$D33),$E33/Assumptions!$B$5,0) -> 0 | N33: =IF(AND(N$4>=$C33,N$4<=$D33),$E33/Assumptions!$B$5,0) -> 0 | O33: =IF(AND(O$4>=$C33,O$4<=$D33),$E33/Assumptions!$B$5,0) -> 0 | P33: =IF(AND(P$4>=$C33,P$4<=$D33),$E33/Assumptions!$B$5,0) -> 0 | Q33: =IF(AND(Q$4>=$C33,Q$4<=$D33),$E33/Assumptions!$B$5,0) -> 0 | ... AG33: =IF(AND(AG$4>=$C33,AG$4<=$D33),$E33/Assumptions!$B$5,0) -> 15461.111
A34: Gen 1 — renews Gen0 Mo.3 | B34: =D8+1 -> 17 | C34: =B34 -> 17 | D34: =C34+Assumptions!$B$5-1 -> 28 | E34: =G34+H34-I34 -> 185533.33 | F34: =E8*Assumptions!$B$26 -> 22000 | G34: =E8-F34 -> 161333.33 | H34: =G34*Assumptions!$B$27 -> 29040 | I34: =G34*Assumptions!$B$28 -> 4840 | J34: =IF(AND(J$4>=$C34,J$4<=$D34),$E34/Assumptions!$B$5,0) -> 0 | K34: =IF(AND(K$4>=$C34,K$4<=$D34),$E34/Assumptions!$B$5,0) -> 0 | L34: =IF(AND(L$4>=$C34,L$4<=$D34),$E34/Assumptions!$B$5,0) -> 0 | M34: =IF(AND(M$4>=$C34,M$4<=$D34),$E34/Assumptions!$B$5,0) -> 0 | N34: =IF(AND(N$4>=$C34,N$4<=$D34),$E34/Assumptions!$B$5,0) -> 0 | O34: =IF(AND(O$4>=$C34,O$4<=$D34),$E34/Assumptions!$B$5,0) -> 0 | P34: =IF(AND(P$4>=$C34,P$4<=$D34),$E34/Assumptions!$B$5,0) -> 0 | Q34: =IF(AND(Q$4>=$C34,Q$4<=$D34),$E34/Assumptions!$B$5,0) -> 0 | ... AG34: =IF(AND(AG$4>=$C34,AG$4<=$D34),$E34/Assumptions!$B$5,0) -> 15461.111
A35: Gen 1 — renews Gen0 Mo.4 | B35: =D9+1 -> 18 | C35: =B35 -> 18 | D35: =C35+Assumptions!$B$5-1 -> 29 | E35: =G35+H35-I35 -> 216146.33 | F35: =E9*Assumptions!$B$26 -> 25630 | G35: =E9-F35 -> 187953.33 | H35: =G35*Assumptions!$B$27 -> 33831.6 | I35: =G35*Assumptions!$B$28 -> 5638.6 | J35: =IF(AND(J$4>=$C35,J$4<=$D35),$E35/Assumptions!$B$5,0) -> 0 | K35: =IF(AND(K$4>=$C35,K$4<=$D35),$E35/Assumptions!$B$5,0) -> 0 | L35: =IF(AND(L$4>=$C35,L$4<=$D35),$E35/Assumptions!$B$5,0) -> 0 | M35: =IF(AND(M$4>=$C35,M$4<=$D35),$E35/Assumptions!$B$5,0) -> 0 | N35: =IF(AND(N$4>=$C35,N$4<=$D35),$E35/Assumptions!$B$5,0) -> 0 | O35: =IF(AND(O$4>=$C35,O$4<=$D35),$E35/Assumptions!$B$5,0) -> 0 | P35: =IF(AND(P$4>=$C35,P$4<=$D35),$E35/Assumptions!$B$5,0) -> 0 | Q35: =IF(AND(Q$4>=$C35,Q$4<=$D35),$E35/Assumptions!$B$5,0) -> 0 | ... AG35: =IF(AND(AG$4>=$C35,AG$4<=$D35),$E35/Assumptions!$B$5,0) -> 18012.194
A36: Gen 1 — renews Gen0 Mo.5 | B36: =D10+1 -> 19 | C36: =B36 -> 19 | D36: =C36+Assumptions!$B$5-1 -> 30 | E36: =G36+H36-I36 -> 246759.33 | F36: =E10*Assumptions!$B$26 -> 29260 | G36: =E10-F36 -> 214573.33 | H36: =G36*Assumptions!$B$27 -> 38623.2 | I36: =G36*Assumptions!$B$28 -> 6437.2 | J36: =IF(AND(J$4>=$C36,J$4<=$D36),$E36/Assumptions!$B$5,0) -> 0 | K36: =IF(AND(K$4>=$C36,K$4<=$D36),$E36/Assumptions!$B$5,0) -> 0 | L36: =IF(AND(L$4>=$C36,L$4<=$D36),$E36/Assumptions!$B$5,0) -> 0 | M36: =IF(AND(M$4>=$C36,M$4<=$D36),$E36/Assumptions!$B$5,0) -> 0 | N36: =IF(AND(N$4>=$C36,N$4<=$D36),$E36/Assumptions!$B$5,0) -> 0 | O36: =IF(AND(O$4>=$C36,O$4<=$D36),$E36/Assumptions!$B$5,0) -> 0 | P36: =IF(AND(P$4>=$C36,P$4<=$D36),$E36/Assumptions!$B$5,0) -> 0 | Q36: =IF(AND(Q$4>=$C36,Q$4<=$D36),$E36/Assumptions!$B$5,0) -> 0 | ... AG36: =IF(AND(AG$4>=$C36,AG$4<=$D36),$E36/Assumptions!$B$5,0) -> 20563.278
A37: Gen 1 — renews Gen0 Mo.6 | B37: =D11+1 -> 20 | C37: =B37 -> 20 | D37: =C37+Assumptions!$B$5-1 -> 31 | E37: =G37+H37-I37 -> 252747 | F37: =E11*Assumptions!$B$26 -> 29970 | G37: =E11-F37 -> 219780 | H37: =G37*Assumptions!$B$27 -> 39560.4 | I37: =G37*Assumptions!$B$28 -> 6593.4 | J37: =IF(AND(J$4>=$C37,J$4<=$D37),$E37/Assumptions!$B$5,0) -> 0 | K37: =IF(AND(K$4>=$C37,K$4<=$D37),$E37/Assumptions!$B$5,0) -> 0 | L37: =IF(AND(L$4>=$C37,L$4<=$D37),$E37/Assumptions!$B$5,0) -> 0 | M37: =IF(AND(M$4>=$C37,M$4<=$D37),$E37/Assumptions!$B$5,0) -> 0 | N37: =IF(AND(N$4>=$C37,N$4<=$D37),$E37/Assumptions!$B$5,0) -> 0 | O37: =IF(AND(O$4>=$C37,O$4<=$D37),$E37/Assumptions!$B$5,0) -> 0 | P37: =IF(AND(P$4>=$C37,P$4<=$D37),$E37/Assumptions!$B$5,0) -> 0 | Q37: =IF(AND(Q$4>=$C37,Q$4<=$D37),$E37/Assumptions!$B$5,0) -> 0 | ... AG37: =IF(AND(AG$4>=$C37,AG$4<=$D37),$E37/Assumptions!$B$5,0) -> 21062.25
A38: Gen 1 — renews Gen0 Mo.7 | B38: =D12+1 -> 21 | C38: =B38 -> 21 | D38: =C38+Assumptions!$B$5-1 -> 32 | E38: =G38+H38-I38 -> 252747 | F38: =E12*Assumptions!$B$26 -> 29970 | G38: =E12-F38 -> 219780 | H38: =G38*Assumptions!$B$27 -> 39560.4 | I38: =G38*Assumptions!$B$28 -> 6593.4 | J38: =IF(AND(J$4>=$C38,J$4<=$D38),$E38/Assumptions!$B$5,0) -> 0 | K38: =IF(AND(K$4>=$C38,K$4<=$D38),$E38/Assumptions!$B$5,0) -> 0 | L38: =IF(AND(L$4>=$C38,L$4<=$D38),$E38/Assumptions!$B$5,0) -> 0 | M38: =IF(AND(M$4>=$C38,M$4<=$D38),$E38/Assumptions!$B$5,0) -> 0 | N38: =IF(AND(N$4>=$C38,N$4<=$D38),$E38/Assumptions!$B$5,0) -> 0 | O38: =IF(AND(O$4>=$C38,O$4<=$D38),$E38/Assumptions!$B$5,0) -> 0 | P38: =IF(AND(P$4>=$C38,P$4<=$D38),$E38/Assumptions!$B$5,0) -> 0 | Q38: =IF(AND(Q$4>=$C38,Q$4<=$D38),$E38/Assumptions!$B$5,0) -> 0 | ... AG38: =IF(AND(AG$4>=$C38,AG$4<=$D38),$E38/Assumptions!$B$5,0) -> 21062.25
A39: Gen 1 — renews Gen0 Mo.8 | B39: =D13+1 -> 22 | C39: =B39 -> 22 | D39: =C39+Assumptions!$B$5-1 -> 33 | E39: =G39+H39-I39 -> 252747 | F39: =E13*Assumptions!$B$26 -> 29970 | G39: =E13-F39 -> 219780 | H39: =G39*Assumptions!$B$27 -> 39560.4 | I39: =G39*Assumptions!$B$28 -> 6593.4 | J39: =IF(AND(J$4>=$C39,J$4<=$D39),$E39/Assumptions!$B$5,0) -> 0 | K39: =IF(AND(K$4>=$C39,K$4<=$D39),$E39/Assumptions!$B$5,0) -> 0 | L39: =IF(AND(L$4>=$C39,L$4<=$D39),$E39/Assumptions!$B$5,0) -> 0 | M39: =IF(AND(M$4>=$C39,M$4<=$D39),$E39/Assumptions!$B$5,0) -> 0 | N39: =IF(AND(N$4>=$C39,N$4<=$D39),$E39/Assumptions!$B$5,0) -> 0 | O39: =IF(AND(O$4>=$C39,O$4<=$D39),$E39/Assumptions!$B$5,0) -> 0 | P39: =IF(AND(P$4>=$C39,P$4<=$D39),$E39/Assumptions!$B$5,0) -> 0 | Q39: =IF(AND(Q$4>=$C39,Q$4<=$D39),$E39/Assumptions!$B$5,0) -> 0 | ... AG39: =IF(AND(AG$4>=$C39,AG$4<=$D39),$E39/Assumptions!$B$5,0) -> 21062.25
A40: Gen 1 — renews Gen0 Mo.9 | B40: =D14+1 -> 23 | C40: =B40 -> 23 | D40: =C40+Assumptions!$B$5-1 -> 34 | E40: =G40+H40-I40 -> 252747 | F40: =E14*Assumptions!$B$26 -> 29970 | G40: =E14-F40 -> 219780 | H40: =G40*Assumptions!$B$27 -> 39560.4 | I40: =G40*Assumptions!$B$28 -> 6593.4 | J40: =IF(AND(J$4>=$C40,J$4<=$D40),$E40/Assumptions!$B$5,0) -> 0 | K40: =IF(AND(K$4>=$C40,K$4<=$D40),$E40/Assumptions!$B$5,0) -> 0 | L40: =IF(AND(L$4>=$C40,L$4<=$D40),$E40/Assumptions!$B$5,0) -> 0 | M40: =IF(AND(M$4>=$C40,M$4<=$D40),$E40/Assumptions!$B$5,0) -> 0 | N40: =IF(AND(N$4>=$C40,N$4<=$D40),$E40/Assumptions!$B$5,0) -> 0 | O40: =IF(AND(O$4>=$C40,O$4<=$D40),$E40/Assumptions!$B$5,0) -> 0 | P40: =IF(AND(P$4>=$C40,P$4<=$D40),$E40/Assumptions!$B$5,0) -> 0 | Q40: =IF(AND(Q$4>=$C40,Q$4<=$D40),$E40/Assumptions!$B$5,0) -> 0 | ... AG40: =IF(AND(AG$4>=$C40,AG$4<=$D40),$E40/Assumptions!$B$5,0) -> 21062.25
A41: Gen 1 — renews Gen0 Mo.10 | B41: =D15+1 -> 24 | C41: =B41 -> 24 | D41: =C41+Assumptions!$B$5-1 -> 35 | E41: =G41+H41-I41 -> 252747 | F41: =E15*Assumptions!$B$26 -> 29970 | G41: =E15-F41 -> 219780 | H41: =G41*Assumptions!$B$27 -> 39560.4 | I41: =G41*Assumptions!$B$28 -> 6593.4 | J41: =IF(AND(J$4>=$C41,J$4<=$D41),$E41/Assumptions!$B$5,0) -> 0 | K41: =IF(AND(K$4>=$C41,K$4<=$D41),$E41/Assumptions!$B$5,0) -> 0 | L41: =IF(AND(L$4>=$C41,L$4<=$D41),$E41/Assumptions!$B$5,0) -> 0 | M41: =IF(AND(M$4>=$C41,M$4<=$D41),$E41/Assumptions!$B$5,0) -> 0 | N41: =IF(AND(N$4>=$C41,N$4<=$D41),$E41/Assumptions!$B$5,0) -> 0 | O41: =IF(AND(O$4>=$C41,O$4<=$D41),$E41/Assumptions!$B$5,0) -> 0 | P41: =IF(AND(P$4>=$C41,P$4<=$D41),$E41/Assumptions!$B$5,0) -> 0 | Q41: =IF(AND(Q$4>=$C41,Q$4<=$D41),$E41/Assumptions!$B$5,0) -> 0 | ... AG41: =IF(AND(AG$4>=$C41,AG$4<=$D41),$E41/Assumptions!$B$5,0) -> 21062.25
A42: Gen 1 — renews Gen0 Mo.11 | B42: =D16+1 -> 25 | C42: =B42 -> 25 | D42: =C42+Assumptions!$B$5-1 -> 36 | E42: =G42+H42-I42 -> 252747 | F42: =E16*Assumptions!$B$26 -> 29970 | G42: =E16-F42 -> 219780 | H42: =G42*Assumptions!$B$27 -> 39560.4 | I42: =G42*Assumptions!$B$28 -> 6593.4 | J42: =IF(AND(J$4>=$C42,J$4<=$D42),$E42/Assumptions!$B$5,0) -> 0 | K42: =IF(AND(K$4>=$C42,K$4<=$D42),$E42/Assumptions!$B$5,0) -> 0 | L42: =IF(AND(L$4>=$C42,L$4<=$D42),$E42/Assumptions!$B$5,0) -> 0 | M42: =IF(AND(M$4>=$C42,M$4<=$D42),$E42/Assumptions!$B$5,0) -> 0 | N42: =IF(AND(N$4>=$C42,N$4<=$D42),$E42/Assumptions!$B$5,0) -> 0 | O42: =IF(AND(O$4>=$C42,O$4<=$D42),$E42/Assumptions!$B$5,0) -> 0 | P42: =IF(AND(P$4>=$C42,P$4<=$D42),$E42/Assumptions!$B$5,0) -> 0 | Q42: =IF(AND(Q$4>=$C42,Q$4<=$D42),$E42/Assumptions!$B$5,0) -> 0 | ... AG42: =IF(AND(AG$4>=$C42,AG$4<=$D42),$E42/Assumptions!$B$5,0) -> 0
...

Sheet Summary
A1: Annual Summary
A2: 'New ARR' sums Gen0 cohorts by GO-LIVE month, not signed month — matches the same definition used in the Python model and dashboard. Logo-count/LTV metrics are out of scope for this Excel version (would need a per-cohort account-count column — a reasonable v2 extension, not built here).
A4: Metric | B4: Year 1 | C4: Year 2
A5: Beginning ARR | B5: 0 | C5: =B11 -> 2256166.7
A6: New ARR (went live) | B6: =SUMIFS('Revenue Recognition'!E6:E29,'Revenue Recognition'!C6:C29,">="&1,'Revenue Recognition'!C6:C29,"<="&12) -> 2256166.7 | C6: =SUMIFS('Revenue Recognition'!E6:E29,'Revenue Recognition'!C6:C29,">="&13,'Revenue Recognition'!C6:C29,"<="&24) -> 2997000
A7: Expansion ARR | B7: =SUMIFS('Revenue Recognition'!H32:H55,'Revenue Recognition'!D6:D29,">="&1,'Revenue Recognition'!D6:D29,"<="&12) -> 0 | C7: =SUMIFS('Revenue Recognition'!H32:H55,'Revenue Recognition'!D6:D29,">="&13,'Revenue Recognition'!D6:D29,"<="&24) -> 396937.2
A8: Contraction ARR | B8: =SUMIFS('Revenue Recognition'!I32:I55,'Revenue Recognition'!D6:D29,">="&1,'Revenue Recognition'!D6:D29,"<="&12) -> 0 | C8: =SUMIFS('Revenue Recognition'!I32:I55,'Revenue Recognition'!D6:D29,">="&13,'Revenue Recognition'!D6:D29,"<="&24) -> 66156.2
A9: Churned ARR | B9: =SUMIFS('Revenue Recognition'!F32:F55,'Revenue Recognition'!D6:D29,">="&1,'Revenue Recognition'!D6:D29,"<="&12) -> 0 | C9: =SUMIFS('Revenue Recognition'!F32:F55,'Revenue Recognition'!D6:D29,">="&13,'Revenue Recognition'!D6:D29,"<="&24) -> 300710
A10: Other / Boundary Effect | B10: =B11-(B5+B6+B7-B8-B9) -> 0 | C10: =C11-(C5+C6+C7-C8-C9) -> -2997
A11: Ending ARR | B11: ='Revenue Recognition'!U58 -> 2256166.7 | C11: ='Revenue Recognition'!AG58 -> 5280240.7
A13: Net Revenue Retention (NRR) | B13: =IFERROR((B5+B7-B8-B9)/B5,"N/A") -> N/A | C13: =IFERROR((C5+C7-C8-C9)/C5,"N/A") -> 1.0133284
A14: Gross $ Churn Rate | B14: =IFERROR(B9/B5,"N/A") -> N/A | C14: =IFERROR(C9/C5,"N/A") -> 0.13328359
A16: Total Revenue Recognized | B16: =SUM('Revenue Recognition'!J57:U57) -> 971194.44 | C16: =SUM('Revenue Recognition'!V57:AG57) -> 3891196
A19: ARR Bridge — Year 2
A20: Beginning ARR | B20: =C5 -> 2256166.7
A21: + New ARR | B21: =C6 -> 2997000
A22: + Expansion ARR | B22: =C7 -> 396937.2
A23: - Contraction ARR | B23: =C8 -> 66156.2
A24: - Churned ARR | B24: =C9 -> 300710
A25: +/- Other / Boundary | B25: =C10 -> -2997
A26: Ending ARR (total) | B26: =C11 -> 5280240.7
